<mujoco model="rh_5_right">
  <compiler angle="radian" autolimits="true"/>

  <option timestep="0.001" integrator="Euler" iterations="5" ls_iterations="8">
    <flag eulerdamp="disable"/>
  </option>

  <asset>
    <texture name="blue_grid" type="2d" builtin="checker"
             rgb1="0.02 0.14 0.44" rgb2="0.27 0.55 1"
             width="300" height="300" mark="edge" markrgb="1 1 1"/>
    <material name="blue_grid" texture="blue_grid"
              texrepeat="1 1" texuniform="true" reflectance="0.2"/>

    <texture name="grey_grid" type="2d" builtin="checker"
             rgb1="0.26 0.26 0.26" rgb2="0.6 0.6 0.6"
             width="300" height="300" mark="edge" markrgb="1 1 1"/>
    <material name="grey_grid" texture="grey_grid"
              texrepeat="1 1" texuniform="true" reflectance="0.2"/>

    <texture type="skybox" builtin="gradient"
             rgb1="0.3 0.5 0.7" rgb2="0 0 0"
             width="512" height="3072"/>

    <texture name="groundplane" type="2d" builtin="checker"
             rgb1="0.2 0.3 0.4" rgb2="0.1 0.2 0.3"
             mark="edge" markrgb="0.8 0.8 0.8"
             width="300" height="300"/>
    <material name="groundplane" texture="groundplane"
              texuniform="true" texrepeat="5 5" reflectance="0.2"/>
    <mesh name="rh_5_base_unit" content_type="model/stl" file="meshes/rh_5_right/rh_5_base_unit.stl" scale="0.001 0.001 0.001"/>
    <mesh name="rh_5_thumb_mcp" content_type="model/stl" file="meshes/rh_5_right/rh_5_thumb_mcp.stl" scale="0.001 0.001 0.001"/>
    <mesh name="rh_5_thumb_mcp2" content_type="model/stl" file="meshes/rh_5_right/rh_5_thumb_mcp2.stl" scale="0.001 0.001 0.001"/>
    <mesh name="rh_5_thumb_ip" content_type="model/stl" file="meshes/rh_5_right/rh_5_thumb_ip.stl" scale="0.001 0.001 0.001"/>
    <mesh name="rh_5_thumb_tip" content_type="model/stl" file="meshes/rh_5_right/rh_5_thumb_tip.stl" scale="0.001 0.001 0.001"/>
    <mesh name="rh_5_finger_mcp" content_type="model/stl" file="meshes/rh_5_right/rh_5_finger_mcp.stl" scale="0.001 0.001 0.001"/>
    <mesh name="rh_5_finger_pip" content_type="model/stl" file="meshes/rh_5_right/rh_5_finger_pip.stl" scale="0.001 0.001 0.001"/>
    <mesh name="rh_5_finger_dip" content_type="model/stl" file="meshes/rh_5_right/rh_5_finger_dip.stl" scale="0.001 0.001 0.001"/>
    <mesh name="rh_5_finger_tip" content_type="model/stl" file="meshes/rh_5_right/rh_5_finger_tip.stl" scale="0.001 0.001 0.001"/>
  </asset>

  <default>
    <default class="rh_5_right">
      <geom friction="0.2" solref="0.02 1.5" solimp="0.9 0.99 0.001" conaffinity="3"/>
      <default class="visual">
        <geom group="2" type="mesh" contype="0" conaffinity="0" density="0"/>
      </default>
      <default class="tip_collision">
        <geom type="capsule" fromto="0 0 0 0 0.0 0.032" friction="0.7 0.05 0.0002" size="0.012" group="3" conaffinity="3"/>
      </default>
      <default class="link_collision">
        <geom type="capsule" fromto="0 0 0 0 0.0 0.025" size="0.012" group="3" conaffinity="3" friction="0.7 0.05 0.0002"/>
      </default>
      <position kp="3.0" inheritrange="1"/>
      <!-- armature = rotor inertia * gear ratio^2 = 1.7 * 1e-8 * 288*288 = 0.00149376 -->
      <!-- max torque = 0.2196 = 600/1000*0.366 -->
      <!-- frictionloss = rough guess, small ish value -->
      <!-- <joint axis="0 0 -1" damping="0.2" armature="0.00149376" frictionloss="0.02" actuatorfrcrange="-0.2196 0.2196"/> -->
      <joint damping="0.2" armature="0.00149376" actuatorfrcrange="-0.2196 0.2196" frictionloss="0.02"/>
    </default>
  </default>

  <!-- avoid consecutive links from contacting each other (because they penetrate each other)-->
  <contact>
    <exclude body1="palm" body2="finger_r_link_1_thumb1"/>
    <exclude body1="palm" body2="finger_r_link_1_thumb2"/>
    <exclude body1="palm" body2="finger_r_link_1_thumb3"/>
    <exclude body1="palm" body2="finger_r_link_2_index1"/>
    <exclude body1="palm" body2="finger_r_link_2_index2"/>
    <exclude body1="palm" body2="finger_r_link_2_index3"/>
    <exclude body1="palm" body2="finger_r_link_3_middle1"/>
    <exclude body1="palm" body2="finger_r_link_3_middle2"/>
    <exclude body1="palm" body2="finger_r_link_3_middle3"/>
    <exclude body1="palm" body2="finger_r_link_4_ring1"/>
    <exclude body1="palm" body2="finger_r_link_4_ring2"/>
    <exclude body1="palm" body2="finger_r_link_4_ring3"/>
    <exclude body1="palm" body2="finger_r_link_5_little1"/>
    <exclude body1="palm" body2="finger_r_link_5_little2"/>
    <exclude body1="palm" body2="finger_r_link_5_little3"/>

    <exclude body1="finger_r_link_1_thumb1" body2="finger_r_link_1_thumb2"/>
    <exclude body1="finger_r_link_1_thumb2" body2="finger_r_link_1_thumb3"/>
    <exclude body1="finger_r_link_1_thumb3" body2="finger_r_link_1_thumb4"/>
    <exclude body1="finger_r_link_2_index1" body2="finger_r_link_2_index2"/>
    <exclude body1="finger_r_link_2_index2" body2="finger_r_link_2_index3"/>
    <exclude body1="finger_r_link_2_index3" body2="finger_r_link_2_index4"/>
    <exclude body1="finger_r_link_3_middle1" body2="finger_r_link_3_middle2"/>
    <exclude body1="finger_r_link_3_middle2" body2="finger_r_link_3_middle3"/>
    <exclude body1="finger_r_link_3_middle3" body2="finger_r_link_3_middle4"/>
    <exclude body1="finger_r_link_3_middle4" body2="finger_r_link_4_ring1"/>
    <exclude body1="finger_r_link_4_ring1" body2="finger_r_link_4_ring2"/>
    <exclude body1="finger_r_link_4_ring2" body2="finger_r_link_4_ring3"/>
    <exclude body1="finger_r_link_4_ring3" body2="finger_r_link_4_ring4"/>
    <exclude body1="finger_r_link_5_little1" body2="finger_r_link_5_little2"/>
    <exclude body1="finger_r_link_5_little2" body2="finger_r_link_5_little3"/>
    <exclude body1="finger_r_link_5_little3" body2="finger_r_link_5_little4"/>
  </contact>

  <worldbody>
    <light pos="0 -0.1 0.5" dir="0 0.2 -1"
           diffuse="0.7 0.7 0.7" specular="0.3 0.3 0.3"
           directional="true" castshadow="true"/>

    <geom name="floor" type="plane" size="0 0 0.05" pos="0 0 -0.2"
          group="0" material="groundplane"
          friction="0.5 0.02 0.02"/>

    <body name="palm" pos="0 0 0" quat="0.7071068 0 0.7071068 0" childclass="rh_5_right">
      <inertial pos="0.0 0 0.05" quat="1 0 0 0" mass="0.265" diaginertia="0.000152 0.0001025 0.0001072"/>
      <joint name="slider_z" type="slide" axis="-1 0 0" 
         limited="true" range="-0.2 0.2" damping="20"
         actuatorfrcrange="-150 150"/>
      <geom name="palm_geom" rgba="0.2 0.2 0.2 1" mesh="rh_5_base_unit" class="visual"/>
      <geom name="palm_collision_1" class="link_collision" fromto="0.01 -0.04 0.01 0.01 -0.04 0.08"/>
      <geom name="palm_collision_2" class="link_collision" fromto="0.01 -0.015 0.01 0.01 -0.015 0.09"/>
      <geom name="palm_collision_3" class="link_collision" fromto="0.01 0.01 0.01 0.01 0.01 0.10"/>
      <geom name="palm_collision_4" class="link_collision" fromto="0.01 0.035 0.01 0.01 0.035 0.09"/>
      <site name="palm_site" pos="0.02 0 0.08" group="4"/>
      <body name="finger_r_link_1_thumb1" pos="0.0145 0.02624 0.05394" quat="0.965926 -0.258819 0 0">
        <inertial pos="0.000361735 0.0139993 -0.000359207" quat="0.609826 0.683784 -0.358317 0.179334" mass="0.0117606" diaginertia="1.32352e-06 1.30254e-06 1.03431e-06"/>
        <joint name="finger_r_joint_1_thumb1" pos="0 0 0" axis="0 0 1" range="-2.2 0" actuatorfrcrange="-1000 1000" damping="0.05"/>
        <geom type="mesh" rgba="0.2 0.2 0.2 1" mesh="rh_5_thumb_mcp" class="visual"/>
        <geom name="finger_r_link_1_thumb1_collision" class="link_collision" fromto="0 0 0 0 0.025 0"/>
        <body name="finger_r_link_1_thumb2" pos="0 0.028 0" quat="0.965926 0.258819 0 0">
          <inertial pos="-1.17166e-05 0.0133869 0.0123764" quat="0.996608 -0.0822418 0.0001347 -0.002849" mass="0.072237" diaginertia="2.01843e-05 1.78046e-05 7.79946e-06"/>
          <joint name="finger_r_joint_1_thumb2" pos="0 0 0" axis="1 0 0" range="-2 0.3" actuatorfrcrange="-1000 1000" damping="0.05"/>
          <geom type="mesh" rgba="0.2 0.2 0.2 1" mesh="rh_5_thumb_mcp2" class="visual"/>
          <geom name="finger_r_link_1_thumb2_collision" class="link_collision" fromto="0 0.015 0 0 0.015 0.025"/>
          <body name="finger_r_link_1_thumb3" pos="0 0.0145 0.035">
            <inertial pos="-4.08055e-06 -0.000101462 0.0241565" quat="0.999803 -0.019813 -0.000125093 0.000704133" mass="0.0346897" diaginertia="5.40298e-06 5.04139e-06 2.25369e-06"/>
            <joint name="finger_r_joint_1_thumb3" pos="0 0 0" axis="0 1 0" range="0 1.57" actuatorfrcrange="-1000 1000" damping="0.05"/>
            <geom type="mesh" rgba="0.2 0.2 0.2 1" mesh="rh_5_thumb_ip" class="visual"/>
            <geom name="finger_r_link_1_thumb3_collision" class="link_collision"/>
            <body name="finger_r_link_1_thumb4" pos="0 0 0.0355">
              <inertial pos="0.000710251 -0.000147171 0.0180986" quat="0.997605 -0.0306215 0.0610988 0.0106714" mass="0.0136372" diaginertia="2.25286e-06 2.02248e-06 1.06005e-06"/>
              <joint name="finger_r_joint_1_thumb4" pos="0 0 0" axis="0 1 0" range="0 1.57" actuatorfrcrange="-1000 1000" damping="0.05"/>
              <geom name="finger_r_link_1_thumb4_geom"type="mesh" rgba="0.2 0.2 0.2 1" mesh="rh_5_thumb_tip" class="visual"/>
              <site name="finger_r_link_1_thumb4_site" pos="0.01 0 0.03" group="4"/>
              <geom name="finger_r_link_1_thumb4_collision" class="tip_collision"/>
            </body>
          </body>
        </body>
      </body>
      <body name="finger_r_link_2_index1" pos="-0.0015 0.03608 0.09575" >
        <inertial pos="0.0051934 -1.81631e-05 0.0211155" quat="0.567409 0.425612 0.423599 0.56344" mass="0.0388044" diaginertia="5.79224e-06 4.82203e-06 3.41556e-06"/>
        <joint name="finger_r_joint_2_index1" pos="0 0 0" axis="1 0 0" range="-0.6 0.6" actuatorfrcrange="-1000 1000" damping="0.05"/>
        <geom type="mesh" rgba="0.2 0.2 0.2 1" mesh="rh_5_finger_mcp" class="visual"/>
        <body name="finger_r_link_2_index2" pos="0.0165 0 0.0235">
          <inertial pos="4.08055e-06 0.000101462 0.0241565" quat="0.999803 0.019813 0.000125093 0.000704133" mass="0.0346897" diaginertia="5.40298e-06 5.04139e-06 2.25369e-06"/>
          <joint name="finger_r_joint_2_index2" pos="0 0 0" axis="0 1 0" range="0 2" actuatorfrcrange="-1000 1000" damping="0.05"/>
          <geom type="mesh" rgba="0.2 0.2 0.2 1" mesh="rh_5_finger_pip" class="visual"/>
          <geom name="finger_r_link_2_index2_collision" class="link_collision"/>
          <body name="finger_r_link_2_index3" pos="0 0 0.0355">
            <inertial pos="4.08055e-06 0.000101462 0.0241565" quat="0.999803 0.019813 0.000125093 0.000704133" mass="0.0346897" diaginertia="5.40298e-06 5.04139e-06 2.25369e-06"/>
            <joint name="finger_r_joint_2_index3" pos="0 0 0" axis="0 1 0" range="0 1.57" actuatorfrcrange="-1000 1000" damping="0.05"/>
            <geom type="mesh" rgba="0.2 0.2 0.2 1" mesh="rh_5_finger_dip" class="visual"/>
            <geom name="finger_r_link_2_index3_collision" class="link_collision"/>
            <body name="finger_r_link_2_index4" pos="0 0 0.0355">
              <inertial pos="0.000710251 0.000472384 0.0180986" quat="0.997106 0.0409408 0.0613191 -0.018508" mass="0.0136372" diaginertia="2.25027e-06 2.02542e-06 1.05421e-06"/>
              <joint name="finger_r_joint_2_index4" pos="0 0 0" axis="0 1 0" range="0 1.57" actuatorfrcrange="-1000 1000" damping="0.05"/>
              <geom name="finger_r_link_2_index4_geom" type="mesh" rgba="0.2 0.2 0.2 1" mesh="rh_5_finger_tip" class="visual"/>
              <geom name="finger_r_link_2_index4_collision" class="tip_collision"/>
              <site name="finger_r_link_2_index4_site" pos="0.01 0 0.03" group="4"/>
            </body>
          </body>
        </body>
      </body>
      <body name="finger_r_link_3_middle1" pos="-0.0015 0.00908 0.10353">
        <inertial pos="0.0051934 -1.81631e-05 0.0211155" quat="0.567409 0.425612 0.423599 0.56344" mass="0.0388044" diaginertia="5.79224e-06 4.82203e-06 3.41556e-06"/>
        <joint name="finger_r_joint_3_middle1" pos="0 0 0" axis="1 0 0" range="-0.6 0.6" actuatorfrcrange="-1000 1000" damping="0.05"/>
        <geom type="mesh" rgba="0.2 0.2 0.2 1" mesh="rh_5_finger_mcp" class="visual"/>
        <body name="finger_r_link_3_middle2" pos="0.0165 0 0.0235">
          <inertial pos="4.08055e-06 0.000101462 0.0241565" quat="0.999803 0.019813 0.000125093 0.000704133" mass="0.0346897" diaginertia="5.40298e-06 5.04139e-06 2.25369e-06"/>
          <joint name="finger_r_joint_3_middle2" pos="0 0 0" axis="0 1 0" range="0 2" actuatorfrcrange="-1000 1000" damping="0.05"/>
          <geom type="mesh" rgba="0.2 0.2 0.2 1" mesh="rh_5_finger_pip" class="visual"/>
          <geom name="finger_r_link_3_middle2_collision" class="link_collision"/>
          <body name="finger_r_link_3_middle3" pos="0 0 0.0355">
            <inertial pos="4.08055e-06 0.000101462 0.0241565" quat="0.999803 0.019813 0.000125093 0.000704133" mass="0.0346897" diaginertia="5.40298e-06 5.04139e-06 2.25369e-06"/>
            <joint name="finger_r_joint_3_middle3" pos="0 0 0" axis="0 1 0" range="0 1.57" actuatorfrcrange="-1000 1000" damping="0.05"/>
            <geom type="mesh" rgba="0.2 0.2 0.2 1" mesh="rh_5_finger_dip" class="visual"/>
            <geom name="finger_r_link_3_middle3_collision" class="link_collision"/>
            <body name="finger_r_link_3_middle4" pos="0 0 0.0355">
              <inertial pos="0.000710251 0.000472384 0.0180986" quat="0.997106 0.0409408 0.0613191 -0.018508" mass="0.0136372" diaginertia="2.25027e-06 2.02542e-06 1.05421e-06"/>
              <joint name="finger_r_joint_3_middle4" pos="0 0 0" axis="0 1 0" range="0 1.57" actuatorfrcrange="-1000 1000" damping="0.05"/>
              <geom name="finger_r_link_3_middle4_geom" type="mesh" rgba="0.2 0.2 0.2 1" mesh="rh_5_finger_tip" class="visual"/>
              <geom name="finger_r_link_3_middle4_collision" class="tip_collision"/>
              <site name="finger_r_link_3_middle4_site" pos="0.01 0 0.03" group="4"/>
            </body>
          </body>
        </body>
      </body>
      <body name="finger_r_link_4_ring1" pos="-0.0015 -0.01792 0.09775">
        <inertial pos="0.0051934 -1.81631e-05 0.0211155" quat="0.567409 0.425612 0.423599 0.56344" mass="0.0388044" diaginertia="5.79224e-06 4.82203e-06 3.41556e-06"/>
        <joint name="finger_r_joint_4_ring1" pos="0 0 0" axis="1 0 0" range="-0.6 0.6" actuatorfrcrange="-1000 1000" damping="0.05"/>
        <geom type="mesh" rgba="0.2 0.2 0.2 1" mesh="rh_5_finger_mcp" class="visual"/>
        <body name="finger_r_link_4_ring2" pos="0.0165 0 0.0235">
          <inertial pos="4.08055e-06 0.000101462 0.0241565" quat="0.999803 0.019813 0.000125093 0.000704133" mass="0.0346897" diaginertia="5.40298e-06 5.04139e-06 2.25369e-06"/>
          <joint name="finger_r_joint_4_ring2" pos="0 0 0" axis="0 1 0" range="0 2" actuatorfrcrange="-1000 1000" damping="0.05"/>
          <geom type="mesh" rgba="0.2 0.2 0.2 1" mesh="rh_5_finger_pip" class="visual"/>
          <geom name="finger_r_link_4_ring2_collision" class="link_collision"/>
          <body name="finger_r_link_4_ring3" pos="0 0 0.0355">
            <inertial pos="4.08055e-06 0.000101462 0.0241565" quat="0.999803 0.019813 0.000125093 0.000704133" mass="0.0346897" diaginertia="5.40298e-06 5.04139e-06 2.25369e-06"/>
            <joint name="finger_r_joint_4_ring3" pos="0 0 0" axis="0 1 0" range="0 1.57" actuatorfrcrange="-1000 1000" damping="0.05"/>
            <geom type="mesh" rgba="0.2 0.2 0.2 1" mesh="rh_5_finger_dip" class="visual"/>
            <geom name="finger_r_link_4_ring3_collision" class="link_collision"/>
            <body name="finger_r_link_4_ring4" pos="0 0 0.0355">
              <inertial pos="0.000710251 0.000472384 0.0180986" quat="0.997106 0.0409408 0.0613191 -0.018508" mass="0.0136372" diaginertia="2.25027e-06 2.02542e-06 1.05421e-06"/>
              <joint name="finger_r_joint_4_ring4" pos="0 0 0" axis="0 1 0" range="0 1.57" actuatorfrcrange="-1000 1000" damping="0.05"/>
              <geom name="finger_r_link_4_ring4_geom" type="mesh" rgba="0.2 0.2 0.2 1" mesh="rh_5_finger_tip" class="visual"/>
              <geom name="finger_r_link_4_ring4_collision" class="tip_collision"/>
              <site name="finger_r_link_4_ring4_site" pos="0.01 0 0.03" group="4"/>
            </body>
          </body>
        </body>
      </body>
      <body name="finger_r_link_5_little1" pos="-0.0015 -0.04492 0.07875">
        <inertial pos="0.0051934 -1.81631e-05 0.0211155" quat="0.567409 0.425612 0.423599 0.56344" mass="0.0388044" diaginertia="5.79224e-06 4.82203e-06 3.41556e-06"/>
        <joint name="finger_r_joint_5_little1" pos="0 0 0" axis="1 0 0" range="-0.6 0.6" actuatorfrcrange="-1000 1000" damping="0.05"/>
        <geom type="mesh" rgba="0.2 0.2 0.2 1" mesh="rh_5_finger_mcp" class="visual"/>
        <body name="finger_r_link_5_little2" pos="0.0165 0 0.0235">
          <inertial pos="4.08055e-06 0.000101462 0.0241565" quat="0.999803 0.019813 0.000125093 0.000704133" mass="0.0346897" diaginertia="5.40298e-06 5.04139e-06 2.25369e-06"/>
          <joint name="finger_r_joint_5_little2" pos="0 0 0" axis="0 1 0" range="0 2" actuatorfrcrange="-1000 1000" damping="0.05"/>
          <geom type="mesh" rgba="0.2 0.2 0.2 1" mesh="rh_5_finger_pip" class="visual"/>
          <geom name="finger_r_link_5_little2_collision" class="link_collision"/>
          <body name="finger_r_link_5_little3" pos="0 0 0.0355">
            <inertial pos="4.08055e-06 0.000101462 0.0241565" quat="0.999803 0.019813 0.000125093 0.000704133" mass="0.0346897" diaginertia="5.40298e-06 5.04139e-06 2.25369e-06"/>
            <joint name="finger_r_joint_5_little3" pos="0 0 0" axis="0 1 0" range="0 1.57" actuatorfrcrange="-1000 1000" damping="0.05"/>
            <geom type="mesh" rgba="0.2 0.2 0.2 1" mesh="rh_5_finger_dip" class="visual"/>
            <geom name="finger_r_link_5_little3_collision" class="link_collision"/>
            <body name="finger_r_link_5_little4" pos="0 0 0.0355">
              <inertial pos="0.000710251 0.000472384 0.0180986" quat="0.997106 0.0409408 0.0613191 -0.018508" mass="0.0136372" diaginertia="2.25027e-06 2.02542e-06 1.05421e-06"/>
              <joint name="finger_r_joint_5_little4" pos="0 0 0" axis="0 1 0" range="0 1.57" actuatorfrcrange="-1000 1000" damping="0.05"/>
              <geom name="finger_r_link_5_little4_geom" type="mesh" rgba="0.2 0.2 0.2 1" mesh="rh_5_finger_tip" class="visual"/>
              <geom name="finger_r_link_5_little4_collision" class="tip_collision"/>
              <site name="finger_r_link_5_little4_site" pos="0.01 0 0.03" group="4"/>
            </body>
          </body>
        </body>
      </body>
    </body>
    <body name="object" pos="0.15 0 -0.1">
      <joint type="free"/>
      <inertial pos="0 0 0" mass="1" diaginertia="0.001 0.001 0.001"/>
      <geom name="object_geom" type="sphere" size="0.04" pos="0.0 0.0 0.0" rgba="0 1 0 1" friction="0.5 0.02 0.02" />
    </body>
  </worldbody>

  <!-- <actuator>
    <position name="slider_z_act" joint="slider_z" kp="500"/>
    <position name="finger_r_joint_1_thumb1_act" joint="finger_r_joint_1_thumb1"/>
    <position name="finger_r_joint_1_thumb2_act" joint="finger_r_joint_1_thumb2"/>
    <position name="finger_r_joint_1_thumb3_act" joint="finger_r_joint_1_thumb3"/>
    <position name="finger_r_joint_1_thumb4_act" joint="finger_r_joint_1_thumb4"/>
    <position name="finger_r_joint_2_index1_act" joint="finger_r_joint_2_index1"/>
    <position name="finger_r_joint_2_index2_act" joint="finger_r_joint_2_index2"/>
    <position name="finger_r_joint_2_index3_act" joint="finger_r_joint_2_index3"/>
    <position name="finger_r_joint_2_index4_act" joint="finger_r_joint_2_index4"/>
    <position name="finger_r_joint_3_middle1_act" joint="finger_r_joint_3_middle1"/>
    <position name="finger_r_joint_3_middle2_act" joint="finger_r_joint_3_middle2"/>
    <position name="finger_r_joint_3_middle3_act" joint="finger_r_joint_3_middle3"/>
    <position name="finger_r_joint_3_middle4_act" joint="finger_r_joint_3_middle4"/>
    <position name="finger_r_joint_4_ring1_act" joint="finger_r_joint_4_ring1"/>
    <position name="finger_r_joint_4_ring2_act" joint="finger_r_joint_4_ring2"/>
    <position name="finger_r_joint_4_ring3_act" joint="finger_r_joint_4_ring3"/>
    <position name="finger_r_joint_4_ring4_act" joint="finger_r_joint_4_ring4"/>
    <position name="finger_r_joint_5_little1_act" joint="finger_r_joint_5_little1"/>
    <position name="finger_r_joint_5_little2_act" joint="finger_r_joint_5_little2"/>
    <position name="finger_r_joint_5_little3_act" joint="finger_r_joint_5_little3"/>
    <position name="finger_r_joint_5_little4_act" joint="finger_r_joint_5_little4"/>
  </actuator> -->
  <actuator>
    <motor name="slider_z_act"   joint="slider_z"    gear="1" ctrllimited="true" ctrlrange="-72 72"/>
    <motor name="finger_r_joint_1_thumb1_act" joint="finger_r_joint_1_thumb1"  gear="1" ctrllimited="true" ctrlrange="-72 72"/>
    <motor name="finger_r_joint_1_thumb2_act" joint="finger_r_joint_1_thumb2"  gear="1" ctrllimited="true" ctrlrange="-72 72"/>
    <motor name="finger_r_joint_1_thumb3_act" joint="finger_r_joint_1_thumb3"  gear="1" ctrllimited="true" ctrlrange="-72 72"/>
    <motor name="finger_r_joint_1_thumb4_act" joint="finger_r_joint_1_thumb4"  gear="1" ctrllimited="true" ctrlrange="-72 72"/>
    <motor name="finger_r_joint_2_index1_act" joint="finger_r_joint_2_index1"  gear="1" ctrllimited="true" ctrlrange="-72 72"/>
    <motor name="finger_r_joint_2_index2_act" joint="finger_r_joint_2_index2"  gear="1" ctrllimited="true" ctrlrange="-72 72"/>
    <motor name="finger_r_joint_2_index3_act" joint="finger_r_joint_2_index3"  gear="1" ctrllimited="true" ctrlrange="-72 72"/>
    <motor name="finger_r_joint_2_index4_act" joint="finger_r_joint_2_index4"  gear="1" ctrllimited="true" ctrlrange="-72 72"/>
    <motor name="finger_r_joint_3_middle1_act" joint="finger_r_joint_3_middle1"  gear="1" ctrllimited="true" ctrlrange="-72 72"/>
    <motor name="finger_r_joint_3_middle2_act" joint="finger_r_joint_3_middle2"  gear="1" ctrllimited="true" ctrlrange="-72 72"/>
    <motor name="finger_r_joint_3_middle3_act" joint="finger_r_joint_3_middle3"  gear="1" ctrllimited="true" ctrlrange="-72 72"/>
    <motor name="finger_r_joint_3_middle4_act" joint="finger_r_joint_3_middle4"  gear="1" ctrllimited="true" ctrlrange="-72 72"/>
    <motor name="finger_r_joint_4_ring1_act" joint="finger_r_joint_4_ring1"  gear="1" ctrllimited="true" ctrlrange="-72 72"/>
    <motor name="finger_r_joint_4_ring2_act" joint="finger_r_joint_4_ring2"  gear="1" ctrllimited="true" ctrlrange="-72 72"/>
    <motor name="finger_r_joint_4_ring3_act" joint="finger_r_joint_4_ring3"  gear="1" ctrllimited="true" ctrlrange="-72 72"/>
    <motor name="finger_r_joint_4_ring4_act" joint="finger_r_joint_4_ring4"  gear="1" ctrllimited="true" ctrlrange="-72 72"/>
    <motor name="finger_r_joint_5_little1_act" joint="finger_r_joint_5_little1"  gear="1" ctrllimited="true" ctrlrange="-72 72"/>
    <motor name="finger_r_joint_5_little2_act" joint="finger_r_joint_5_little2"  gear="1" ctrllimited="true" ctrlrange="-72 72"/>
    <motor name="finger_r_joint_5_little3_act" joint="finger_r_joint_5_little3"  gear="1" ctrllimited="true" ctrlrange="-72 72"/>
    <motor name="finger_r_joint_5_little4_act" joint="finger_r_joint_5_little4"  gear="1" ctrllimited="true" ctrlrange="-72 72"/>
  </actuator>

  <sensor>
    <!-- hand. -->
    <framepos name="palm_position" objtype="site" objname="palm_site"/>
    <framepos name="fingertip4_position" objtype="site" objname="finger_r_link_1_thumb4_site"/> <!--reftype="site" refname="grasp_site"/>-->
    <framepos name="fingertip8_position" objtype="site" objname="finger_r_link_2_index4_site"/>
    <framepos name="fingertip12_position" objtype="site" objname="finger_r_link_3_middle4_site"/>
    <framepos name="fingertip16_position" objtype="site" objname="finger_r_link_4_ring4_site"/>
    <framepos name="fingertip20_position" objtype="site" objname="finger_r_link_5_little4_site"/>
  </sensor>
</mujoco>
